{"status": "passed", "name": "Failing when using MERGE on a relationship that is already bound", "labels": [{"name": "severity", "value": "normal"}, {"name": "feature", "value": "SemanticErrorAcceptance"}, {"name": "framework", "value": "behave"}, {"name": "language", "value": "cpython2"}], "stop": 1578486140019, "historyId": "82cbe4a1819e1eb5a01dfc4e3d809a15", "start": 1578486139805, "steps": [{"status": "passed", "start": 1578486139807, "stop": 1578486140015, "name": "Given any graph"}, {"status": "passed", "start": 1578486140015, "stop": 1578486140018, "name": "When executing query", "attachments": [{"source": "a3b462da-4227-4782-a7f5-9a57b0e5aa24-attachment.txt", "type": "text/plain", "name": ".text"}]}, {"status": "passed", "start": 1578486140018, "stop": 1578486140018, "name": "Then a SyntaxError should be raised at compile time: VariableAlreadyBound"}], "uuid": "1c58307c-5944-408f-8685-60cebf67301e"}