{"status": "failed", "name": "Failing when using CREATE on a node that is already bound", "labels": [{"name": "severity", "value": "normal"}, {"name": "tag", "value": "skip"}, {"name": "feature", "value": "SemanticErrorAcceptance"}, {"name": "framework", "value": "behave"}, {"name": "language", "value": "cpython2"}], "stop": 1578486139368, "historyId": "fc9056bde2688fd4a0af7c50fdba8eac", "start": 1578486139157, "steps": [{"status": "passed", "start": 1578486139158, "stop": 1578486139362, "name": "Given any graph"}, {"status": "passed", "start": 1578486139363, "stop": 1578486139366, "name": "When executing query", "attachments": [{"source": "fb09fd8b-f93a-4d42-9c3d-51f6adac6dfb-attachment.txt", "type": "text/plain", "name": ".text"}]}, {"status": "failed", "start": 1578486139366, "stop": 1578486139367, "name": "Then a SyntaxError should be raised at compile time: VariableAlreadyBound", "statusDetails": {"message": "AssertionError\n", "trace": "  File \"/home/laptop-linux/.local/lib/python2.7/site-packages/behave/model.py\", line 1329, in run\n    match.run(runner.context)\n  File \"/home/laptop-linux/.local/lib/python2.7/site-packages/behave/matchers.py\", line 98, in run\n    self.func(context, *args, **kwargs)\n  File \"features/steps/Steps.py\", line 122, in step_impl\n    assert exception != None\n"}}], "statusDetails": {"message": "AssertionError\n", "trace": "  File \"/home/laptop-linux/.local/lib/python2.7/site-packages/behave/model.py\", line 1329, in run\n    match.run(runner.context)\n  File \"/home/laptop-linux/.local/lib/python2.7/site-packages/behave/matchers.py\", line 98, in run\n    self.func(context, *args, **kwargs)\n  File \"features/steps/Steps.py\", line 122, in step_impl\n    assert exception != None\n"}, "uuid": "d776f324-28e7-4b4f-beed-7e6cc9bb03b4"}