{"status": "failed", "name": "Failing when using a variable that is already bound in CREATE", "labels": [{"name": "severity", "value": "normal"}, {"name": "tag", "value": "skip"}, {"name": "feature", "value": "MiscellaneousErrorAcceptance"}, {"name": "framework", "value": "behave"}, {"name": "language", "value": "cpython2"}], "stop": 1578486099555, "historyId": "982e6a7b4838c8c718621111fd303dfb", "start": 1578486099340, "steps": [{"status": "passed", "start": 1578486099342, "stop": 1578486099549, "name": "Given any graph"}, {"status": "passed", "start": 1578486099549, "stop": 1578486099552, "name": "When executing query", "attachments": [{"source": "850748e8-ff42-4d4b-ac1e-a9d6474fb7b3-attachment.txt", "type": "text/plain", "name": ".text"}]}, {"status": "failed", "start": 1578486099553, "stop": 1578486099554, "name": "Then a SyntaxError should be raised at compile time: VariableAlreadyBound", "statusDetails": {"message": "AssertionError\n", "trace": "  File \"/home/laptop-linux/.local/lib/python2.7/site-packages/behave/model.py\", line 1329, in run\n    match.run(runner.context)\n  File \"/home/laptop-linux/.local/lib/python2.7/site-packages/behave/matchers.py\", line 98, in run\n    self.func(context, *args, **kwargs)\n  File \"features/steps/Steps.py\", line 122, in step_impl\n    assert exception != None\n"}}], "statusDetails": {"message": "AssertionError\n", "trace": "  File \"/home/laptop-linux/.local/lib/python2.7/site-packages/behave/model.py\", line 1329, in run\n    match.run(runner.context)\n  File \"/home/laptop-linux/.local/lib/python2.7/site-packages/behave/matchers.py\", line 98, in run\n    self.func(context, *args, **kwargs)\n  File \"features/steps/Steps.py\", line 122, in step_impl\n    assert exception != None\n"}, "uuid": "8981ac20-03b0-4b44-9d8a-8c9a89e16974"}